Workbook

Sheet קידוד_ניסוי
A1: Participant_ID | B1: סדר_מודלים | C1: מודל A | D1: מודל B | E1: תרגול_R1_Scenario_ID | F1: תרגול_R1_קושי | G1: תרגול_R2_Scenario_ID | H1: תרגול_R2_קושי | I1: תרגול_R3_Scenario_ID | J1: תרגול_R3_קושי | K1: תרגול_R4_Scenario_ID | L1: תרגול_R4_קושי | M1: תרגול_R5_Scenario_ID | N1: תרגול_R5_קושי | O1: תרגול_R6_Scenario_ID | P1: תרגול_R6_קושי | Q1: מודל_1_סוג_מודל | R1: מודל_1_סדר_ויזואליזציות | S1: מודל_1_VIS1_ויזואליזציה | T1: מודל_1_VIS1_R1_Scenario_ID | U1: מודל_1_VIS1_R1_קושי | V1: מודל_1_VIS1_R2_Scenario_ID | W1: מודל_1_VIS1_R2_קושי | X1: מודל_1_VIS1_R3_Scenario_ID | Y1: מודל_1_VIS1_R3_קושי | Z1: מודל_1_VIS1_R4_Scenario_ID | AA1: מודל_1_VIS1_R4_קושי | AB1: מודל_1_VIS1_R5_Scenario_ID | AC1: מודל_1_VIS1_R5_קושי | AD1: מודל_1_VIS2_ויזואליזציה | AE1: מודל_1_VIS2_R1_Scenario_ID | AF1: מודל_1_VIS2_R1_קושי | AG1: מודל_1_VIS2_R2_Scenario_ID | AH1: מודל_1_VIS2_R2_קושי | AI1: מודל_1_VIS2_R3_Scenario_ID | AJ1: מודל_1_VIS2_R3_קושי | AK1: מודל_1_VIS2_R4_Scenario_ID | AL1: מודל_1_VIS2_R4_קושי | AM1: מודל_1_VIS2_R5_Scenario_ID | AN1: מודל_1_VIS2_R5_קושי | AO1: מודל_1_VIS3_ויזואליזציה | AP1: מודל_1_VIS3_R1_Scenario_ID | AQ1: מודל_1_VIS3_R1_קושי | AR1: מודל_1_VIS3_R2_Scenario_ID | AS1: מודל_1_VIS3_R2_קושי | AT1: מודל_1_VIS3_R3_Scenario_ID | AU1: מודל_1_VIS3_R3_קושי | AV1: מודל_1_VIS3_R4_Scenario_ID | AW1: מודל_1_VIS3_R4_קושי | AX1: מודל_1_VIS3_R5_Scenario_ID | AY1: מודל_1_VIS3_R5_קושי | AZ1: מודל_2_סוג_מודל | BA1: מודל_2_סדר_ויזואליזציות | BB1: מודל_2_VIS1_ויזואליזציה | BC1: מודל_2_VIS1_R1_Scenario_ID | BD1: מודל_2_VIS1_R1_קושי | BE1: מודל_2_VIS1_R2_Scenario_ID | BF1: מודל_2_VIS1_R2_קושי | BG1: מודל_2_VIS1_R3_Scenario_ID | BH1: מודל_2_VIS1_R3_קושי | BI1: מודל_2_VIS1_R4_Scenario_ID | BJ1: מודל_2_VIS1_R4_קושי | BK1: מודל_2_VIS1_R5_Scenario_ID | BL1: מודל_2_VIS1_R5_קושי | BM1: מודל_2_VIS2_ויזואליזציה | BN1: מודל_2_VIS2_R1_Scenario_ID | BO1: מודל_2_VIS2_R1_קושי | BP1: מודל_2_VIS2_R2_Scenario_ID | BQ1: מודל_2_VIS2_R2_קושי | BR1: מודל_2_VIS2_R3_Scenario_ID | BS1: מודל_2_VIS2_R3_קושי | BT1: מודל_2_VIS2_R4_Scenario_ID | BU1: מודל_2_VIS2_R4_קושי | BV1: מודל_2_VIS2_R5_Scenario_ID | BW1: מודל_2_VIS2_R5_קושי | BX1: מודל_2_VIS3_ויזואליזציה | BY1: מודל_2_VIS3_R1_Scenario_ID | BZ1: מודל_2_VIS3_R1_קושי | CA1: מודל_2_VIS3_R2_Scenario_ID | CB1: מודל_2_VIS3_R2_קושי | CC1: מודל_2_VIS3_R3_Scenario_ID | CD1: מודל_2_VIS3_R3_קושי | CE1: מודל_2_VIS3_R4_Scenario_ID | CF1: מודל_2_VIS3_R4_קושי | CG1: מודל_2_VIS3_R5_Scenario_ID | CH1: מודל_2_VIS3_R5_קושי
A2: P001 | B2: אופטימלי ← תת-אופטימלי | C2: עמודות נערמות ← רדאר ← מפת חום | D2: רדאר ← מפת חום ← עמודות נערמות | E2: SCN_001_S | F2: E | G2: SCN_031_S | H2: E | I2: SCN_002_R | J2: E | K2: SCN_032_R | L2: E | M2: SCN_003_H | N2: E | O2: SCN_033_H | P2: E | Q2: OPT | R2: עמודות נערמות ← רדאר ← מפת חום | S2: עמודות נערמות | T2: SCN_028_S | U2: H | V2: SCN_030_S | W2: E | X2: SCN_026_S | Y2: H | Z2: SCN_027_S | AA2: E | AB2: SCN_024_S | AC2: H | AD2: רדאר | AE2: SCN_014_R | AF2: E | AG2: SCN_016_R | AH2: H | AI2: SCN_017_R | AJ2: E | AK2: SCN_012_R | AL2: H | AM2: SCN_025_R | AN2: E | AO2: מפת חום | AP2: SCN_007_H | AQ2: E | AR2: SCN_006_H | AS2: H | AT2: SCN_004_H | AU2: E | AV2: SCN_008_H | AW2: H | AX2: SCN_009_H | AY2: E | AZ2: SUB | BA2: רדאר ← מפת חום ← עמודות נערמות | BB2: רדאר | BC2: SCN_015_R | BD2: E | BE2: SCN_018_R | BF2: H | BG2: SCN_019_R | BH2: E | BI2: SCN_020_R | BJ2: H | BM2: מפת חום | BN2: SCN_005_H | BO2: E | BP2: SCN_013_H | BQ2: H | BR2: SCN_011_H | BS2: E | BT2: SCN_010_H | BU2: H | BX2: עמודות נערמות | BY2: SCN_023_S | BZ2: E | CA2: SCN_029_S | CB2: H | CC2: SCN_021_S | CD2: E | CE2: SCN_022_S | CF2: H
A3: P002 | B3: תת-אופטימלי ← אופטימלי | C3: מפת חום ← עמודות נערמות ← רדאר | D3: רדאר ← מפת חום ← עמודות נערמות | E3: SCN_001_S | F3: E | G3: SCN_031_S | H3: E | I3: SCN_002_R | J3: E | K3: SCN_032_R | L3: E | M3: SCN_003_H | N3: E | O3: SCN_033_H | P3: E | Q3: SUB | R3: מפת חום ← עמודות נערמות ← רדאר | S3: מפת חום | T3: SCN_005_H | U3: E | V3: SCN_010_H | W3: H | X3: SCN_011_H | Y3: E | Z3: SCN_013_H | AA3: H | AD3: עמודות נערמות | AE3: SCN_023_S | AF3: E | AG3: SCN_022_S | AH3: H | AI3: SCN_021_S | AJ3: E | AK3: SCN_029_S | AL3: H | AO3: רדאר | AP3: SCN_015_R | AQ3: E | AR3: SCN_018_R | AS3: H | AT3: SCN_019_R | AU3: E | AV3: SCN_020_R | AW3: H | AZ3: OPT | BA3: רדאר ← מפת חום ← עמודות נערמות | BB3: רדאר | BC3: SCN_025_R | BD3: E | BE3: SCN_012_R | BF3: H | BG3: SCN_014_R | BH3: E | BI3: SCN_016_R | BJ3: H | BK3: SCN_017_R | BL3: E | BM3: מפת חום | BN3: SCN_007_H | BO3: E | BP3: SCN_006_H | BQ3: H | BR3: SCN_004_H | BS3: E | BT3: SCN_008_H | BU3: H | BV3: SCN_009_H | BW3: E | BX3: עמודות נערמות | BY3: SCN_024_S | BZ3: H | CA3: SCN_027_S | CB3: E | CC3: SCN_026_S | CD3: H | CE3: SCN_030_S | CF3: E | CG3: SCN_028_S | CH3: H
A4: P003 | B4: אופטימלי ← תת-אופטימלי | C4: מפת חום ← עמודות נערמות ← רדאר | D4: עמודות נערמות ← רדאר ← מפת חום | E4: SCN_001_S | F4: E | G4: SCN_031_S | H4: E | I4: SCN_002_R | J4: E | K4: SCN_032_R | L4: E | M4: SCN_003_H | N4: E | O4: SCN_033_H | P4: E | Q4: OPT | R4: מפת חום ← עמודות נערמות ← רדאר | S4: מפת חום | T4: SCN_009_H | U4: E | V4: SCN_008_H | W4: H | X4: SCN_004_H | Y4: E | Z4: SCN_006_H | AA4: H | AB4: SCN_007_H | AC4: E | AD4: עמודות נערמות | AE4: SCN_024_S | AF4: H | AG4: SCN_027_S | AH4: E | AI4: SCN_026_S | AJ4: H | AK4: SCN_030_S | AL4: E | AM4: SCN_028_S | AN4: H | AO4: רדאר | AP4: SCN_014_R | AQ4: E | AR4: SCN_016_R | AS4: H | AT4: SCN_025_R | AU4: E | AV4: SCN_012_R | AW4: H | AX4: SCN_017_R | AY4: E | AZ4: SUB | BA4: עמודות נערמות ← רדאר ← מפת חום | BB4: עמודות נערמות | BC4: SCN_023_S | BD4: E | BE4: SCN_022_S | BF4: H | BG4: SCN_021_S | BH4: E | BI4: SCN_029_S | BJ4: H | BM4: רדאר | BN4: SCN_019_R | BO4: E | BP4: SCN_020_R | BQ4: H | BR4: SCN_015_R | BS4: E | BT4: SCN_018_R | BU4: H | BX4: מפת חום | BY4: SCN_005_H | BZ4: E | CA4: SCN_010_H | CB4: H | CC4: SCN_011_H | CD4: E | CE4: SCN_013_H | CF4: H
A5: P004 | B5: תת-אופטימלי ← אופטימלי | C5: רדאר ← מפת חום ← עמודות נערמות | D5: עמודות נערמות ← רדאר ← מפת חום | E5: SCN_001_S | F5: E | G5: SCN_031_S | H5: E | I5: SCN_002_R | J5: E | K5: SCN_032_R | L5: E | M5: SCN_003_H | N5: E | O5: SCN_033_H | P5: E | Q5: SUB | R5: רדאר ← מפת חום ← עמודות נערמות | S5: רדאר | T5: SCN_019_R | U5: E | V5: SCN_020_R | W5: H | X5: SCN_015_R | Y5: E | Z5: SCN_018_R | AA5: H | AD5: מפת חום | AE5: SCN_011_H | AF5: E | AG5: SCN_010_H | AH5: H | AI5: SCN_005_H | AJ5: E | AK5: SCN_013_H | AL5: H | AO5: עמודות נערמות | AP5: SCN_023_S | AQ5: E | AR5: SCN_022_S | AS5: H | AT5: SCN_021_S | AU5: E | AV5: SCN_029_S | AW5: H | AZ5: OPT | BA5: עמודות נערמות ← רדאר ← מפת חום | BB5: עמודות נערמות | BC5: SCN_026_S | BD5: H | BE5: SCN_030_S | BF5: E | BG5: SCN_024_S | BH5: H | BI5: SCN_027_S | BJ5: E | BK5: SCN_028_S | BL5: H | BM5: רדאר | BN5: SCN_014_R | BO5: E | BP5: SCN_012_R | BQ5: H | BR5: SCN_017_R | BS5: E | BT5: SCN_016_R | BU5: H | BV5: SCN_025_R | BW5: E | BX5: מפת חום | BY5: SCN_009_H | BZ5: E | CA5: SCN_006_H | CB5: H | CC5: SCN_004_H | CD5: E | CE5: SCN_008_H | CF5: H | CG5: SCN_007_H | CH5: E
A6: P005 | B6: אופטימלי ← תת-אופטימלי | C6: רדאר ← מפת חום ← עמודות נערמות | D6: מפת חום ← עמודות נערמות ← רדאר | E6: SCN_001_S | F6: E | G6: SCN_031_S | H6: E | I6: SCN_002_R | J6: E | K6: SCN_032_R | L6: E | M6: SCN_003_H | N6: E | O6: SCN_033_H | P6: E | Q6: OPT | R6: רדאר ← מפת חום ← עמודות נערמות | S6: רדאר | T6: SCN_017_R | U6: E | V6: SCN_016_R | W6: H | X6: SCN_025_R | Y6: E | Z6: SCN_012_R | AA6: H | AB6: SCN_014_R | AC6: E | AD6: מפת חום | AE6: SCN_007_H | AF6: E | AG6: SCN_008_H | AH6: H | AI6: SCN_009_H | AJ6: E | AK6: SCN_006_H | AL6: H | AM6: SCN_004_H | AN6: E | AO6: עמודות נערמות | AP6: SCN_024_S | AQ6: H | AR6: SCN_027_S | AS6: E | AT6: SCN_028_S | AU6: H | AV6: SCN_030_S | AW6: E | AX6: SCN_026_S | AY6: H | AZ6: SUB | BA6: מפת חום ← עמודות נערמות ← רדאר | BB6: מפת חום | BC6: SCN_005_H | BD6: E | BE6: SCN_010_H | BF6: H | BG6: SCN_011_H | BH6: E | BI6: SCN_013_H | BJ6: H | BM6: עמודות נערמות | BN6: SCN_023_S | BO6: E | BP6: SCN_029_S | BQ6: H | BR6: SCN_021_S | BS6: E | BT6: SCN_022_S | BU6: H | BX6: רדאר | BY6: SCN_015_R | BZ6: E | CA6: SCN_018_R | CB6: H | CC6: SCN_019_R | CD6: E | CE6: SCN_020_R | CF6: H
A7: P006 | B7: תת-אופטימלי ← אופטימלי | C7: עמודות נערמות ← רדאר ← מפת חום | D7: מפת חום ← עמודות נערמות ← רדאר | E7: SCN_001_S | F7: E | G7: SCN_031_S | H7: E | I7: SCN_002_R | J7: E | K7: SCN_032_R | L7: E | M7: SCN_003_H | N7: E | O7: SCN_033_H | P7: E | Q7: SUB | R7: עמודות נערמות ← רדאר ← מפת חום | S7: עמודות נערמות | T7: SCN_021_S | U7: E | V7: SCN_022_S | W7: H | X7: SCN_023_S | Y7: E | Z7: SCN_029_S | AA7: H | AD7: רדאר | AE7: SCN_019_R | AF7: E | AG7: SCN_020_R | AH7: H | AI7: SCN_015_R | AJ7: E | AK7: SCN_018_R | AL7: H | AO7: מפת חום | AP7: SCN_005_H | AQ7: E | AR7: SCN_010_H | AS7: H | AT7: SCN_011_H | AU7: E | AV7: SCN_013_H | AW7: H | AZ7: OPT | BA7: מפת חום ← עמודות נערמות ← רדאר | BB7: מפת חום | BC7: SCN_009_H | BD7: E | BE7: SCN_006_H | BF7: H | BG7: SCN_004_H | BH7: E | BI7: SCN_008_H | BJ7: H | BK7: SCN_007_H | BL7: E | BM7: עמודות נערמות | BN7: SCN_026_S | BO7: H | BP7: SCN_027_S | BQ7: E | BR7: SCN_024_S | BS7: H | BT7: SCN_030_S | BU7: E | BV7: SCN_028_S | BW7: H | BX7: רדאר | BY7: SCN_017_R | BZ7: E | CA7: SCN_016_R | CB7: H | CC7: SCN_014_R | CD7: E | CE7: SCN_012_R | CF7: H | CG7: SCN_025_R | CH7: E
A8: P007 | B8: אופטימלי ← תת-אופטימלי | C8: עמודות נערמות ← רדאר ← מפת חום | D8: רדאר ← מפת חום ← עמודות נערמות | E8: SCN_001_S | F8: E | G8: SCN_031_S | H8: E | I8: SCN_002_R | J8: E | K8: SCN_032_R | L8: E | M8: SCN_003_H | N8: E | O8: SCN_033_H | P8: E | Q8: OPT | R8: עמודות נערמות ← רדאר ← מפת חום | S8: עמודות נערמות | T8: SCN_026_S | U8: H | V8: SCN_030_S | W8: E | X8: SCN_024_S | Y8: H | Z8: SCN_027_S | AA8: E | AB8: SCN_028_S | AC8: H | AD8: רדאר | AE8: SCN_017_R | AF8: E | AG8: SCN_012_R | AH8: H | AI8: SCN_025_R | AJ8: E | AK8: SCN_016_R | AL8: H | AM8: SCN_014_R | AN8: E | AO8: מפת חום | AP8: SCN_004_H | AQ8: E | AR8: SCN_006_H | AS8: H | AT8: SCN_007_H | AU8: E | AV8: SCN_008_H | AW8: H | AX8: SCN_009_H | AY8: E | AZ8: SUB | BA8: רדאר ← מפת חום ← עמודות נערמות | BB8: רדאר | BC8: SCN_015_R | BD8: E | BE8: SCN_018_R | BF8: H | BG8: SCN_019_R | BH8: E | BI8: SCN_020_R | BJ8: H | BM8: מפת חום | BN8: SCN_005_H | BO8: E | BP8: SCN_010_H | BQ8: H | BR8: SCN_011_H | BS8: E | BT8: SCN_013_H | BU8: H | BX8: עמודות נערמות | BY8: SCN_021_S | BZ8: E | CA8: SCN_029_S | CB8: H | CC8: SCN_023_S | CD8: E | CE8: SCN_022_S | CF8: H
A9: P008 | B9: תת-אופטימלי ← אופטימלי | C9: מפת חום ← עמודות נערמות ← רדאר | D9: רדאר ← מפת חום ← עמודות נערמות | E9: SCN_001_S | F9: E | G9: SCN_031_S | H9: E | I9: SCN_002_R | J9: E | K9: SCN_032_R | L9: E | M9: SCN_003_H | N9: E | O9: SCN_033_H | P9: E | Q9: SUB | R9: מפת חום ← עמודות נערמות ← רדאר | S9: מפת חום | T9: SCN_011_H | U9: E | V9: SCN_010_H | W9: H | X9: SCN_005_H | Y9: E | Z9: SCN_013_H | AA9: H | AD9: עמודות נערמות | AE9: SCN_023_S | AF9: E | AG9: SCN_029_S | AH9: H | AI9: SCN_021_S | AJ9: E | AK9: SCN_022_S | AL9: H | AO9: רדאר | AP9: SCN_019_R | AQ9: E | AR9: SCN_018_R | AS9: H | AT9: SCN_015_R | AU9: E | AV9: SCN_020_R | AW9: H | AZ9: OPT | BA9: רדאר ← מפת חום ← עמודות נערמות | BB9: רדאר | BC9: SCN_014_R | BD9: E | BE9: SCN_012_R | BF9: H | BG9: SCN_025_R | BH9: E | BI9: SCN_016_R | BJ9: H | BK9: SCN_017_R | BL9: E | BM9: מפת חום | BN9: SCN_004_H | BO9: E | BP9: SCN_008_H | BQ9: H | BR9: SCN_009_H | BS9: E | BT9: SCN_006_H | BU9: H | BV9: SCN_007_H | BW9: E | BX9: עמודות נערמות | BY9: SCN_026_S | BZ9: H | CA9: SCN_027_S | CB9: E | CC9: SCN_024_S | CD9: H | CE9: SCN_030_S | CF9: E | CG9: SCN_028_S | CH9: H
A10: P009 | B10: אופטימלי ← תת-אופטימלי | C10: מפת חום ← עמודות נערמות ← רדאר | D10: עמודות נערמות ← רדאר ← מפת חום | E10: SCN_001_S | F10: E | G10: SCN_031_S | H10: E | I10: SCN_002_R | J10: E | K10: SCN_032_R | L10: E | M10: SCN_003_H | N10: E | O10: SCN_033_H | P10: E | Q10: OPT | R10: מפת חום ← עמודות נערמות ← רדאר | S10: מפת חום | T10: SCN_009_H | U10: E | V10: SCN_006_H | W10: H | X10: SCN_004_H | Y10: E | Z10: SCN_008_H | AA10: H | AB10: SCN_007_H | AC10: E | AD10: עמודות נערמות | AE10: SCN_026_S | AF10: H | AG10: SCN_027_S | AH10: E | AI10: SCN_028_S | AJ10: H | AK10: SCN_030_S | AL10: E | AM10: SCN_024_S | AN10: H | AO10: רדאר | AP10: SCN_014_R | AQ10: E | AR10: SCN_016_R | AS10: H | AT10: SCN_025_R | AU10: E | AV10: SCN_012_R | AW10: H | AX10: SCN_017_R | AY10: E | AZ10: SUB | BA10: עמודות נערמות ← רדאר ← מפת חום | BB10: עמודות נערמות | BC10: SCN_023_S | BD10: E | BE10: SCN_022_S | BF10: H | BG10: SCN_021_S | BH10: E | BI10: SCN_029_S | BJ10: H | BM10: רדאר | BN10: SCN_015_R | BO10: E | BP10: SCN_020_R | BQ10: H | BR10: SCN_019_R | BS10: E | BT10: SCN_018_R | BU10: H | BX10: מפת חום | BY10: SCN_011_H | BZ10: E | CA10: SCN_013_H | CB10: H | CC10: SCN_005_H | CD10: E | CE10: SCN_010_H | CF10: H
A11: P010 | B11: תת-אופטימלי ← אופטימלי | C11: רדאר ← מפת חום ← עמודות נערמות | D11: עמודות נערמות ← רדאר ← מפת חום | E11: SCN_001_S | F11: E | G11: SCN_031_S | H11: E | I11: SCN_002_R | J11: E | K11: SCN_032_R | L11: E | M11: SCN_003_H | N11: E | O11: SCN_033_H | P11: E | Q11: SUB | R11: רדאר ← מפת חום ← עמודות נערמות | S11: רדאר | T11: SCN_015_R | U11: E | V11: SCN_020_R | W11: H | X11: SCN_019_R | Y11: E | Z11: SCN_018_R | AA11: H | AD11: מפת חום | AE11: SCN_011_H | AF11: E | AG11: SCN_013_H | AH11: H | AI11: SCN_005_H | AJ11: E | AK11: SCN_010_H | AL11: H | AO11: עמודות נערמות | AP11: SCN_021_S | AQ11: E | AR11: SCN_022_S | AS11: H | AT11: SCN_023_S | AU11: E | AV11: SCN_029_S | AW11: H | AZ11: OPT | BA11: עמודות נערמות ← רדאר ← מפת חום | BB11: עמודות נערמות | BC11: SCN_028_S | BD11: H | BE11: SCN_027_S | BF11: E | BG11: SCN_026_S | BH11: H | BI11: SCN_030_S | BJ11: E | BK11: SCN_024_S | BL11: H | BM11: רדאר | BN11: SCN_014_R | BO11: E | BP11: SCN_016_R | BQ11: H | BR11: SCN_017_R | BS11: E | BT11: SCN_012_R | BU11: H | BV11: SCN_025_R | BW11: E | BX11: מפת חום | BY11: SCN_009_H | BZ11: E | CA11: SCN_008_H | CB11: H | CC11: SCN_004_H | CD11: E | CE11: SCN_006_H | CF11: H | CG11: SCN_007_H | CH11: E
A12: P011 | B12: אופטימלי ← תת-אופטימלי | C12: רדאר ← מפת חום ← עמודות נערמות | D12: מפת חום ← עמודות נערמות ← רדאר | E12: SCN_001_S | F12: E | G12: SCN_031_S | H12: E | I12: SCN_002_R | J12: E | K12: SCN_032_R | L12: E | M12: SCN_003_H | N12: E | O12: SCN_033_H | P12: E | Q12: OPT | R12: רדאר ← מפת חום ← עמודות נערמות | S12: רדאר | T12: SCN_024_R | U12: H | V12: SCN_030_R | W12: E | X12: SCN_026_R | Y12: H | Z12: SCN_027_R | AA12: E | AB12: SCN_028_R | AC12: H | AD12: מפת חום | AE12: SCN_017_H | AF12: E | AG12: SCN_016_H | AH12: H | AI12: SCN_025_H | AJ12: E | AK12: SCN_012_H | AL12: H | AM12: SCN_014_H | AN12: E | AO12: עמודות נערמות | AP12: SCN_009_S | AQ12: E | AR12: SCN_008_S | AS12: H | AT12: SCN_004_S | AU12: E | AV12: SCN_006_S | AW12: H | AX12: SCN_007_S | AY12: E | AZ12: SUB | BA12: מפת חום ← עמודות נערמות ← רדאר | BB12: מפת חום | BC12: SCN_019_H | BD12: E | BE12: SCN_020_H | BF12: H | BG12: SCN_015_H | BH12: E | BI12: SCN_018_H | BJ12: H | BM12: עמודות נערמות | BN12: SCN_011_S | BO12: E | BP12: SCN_010_S | BQ12: H | BR12: SCN_005_S | BS12: E | BT12: SCN_013_S | BU12: H | BX12: רדאר | BY12: SCN_023_R | BZ12: E | CA12: SCN_029_R | CB12: H | CC12: SCN_021_R | CD12: E | CE12: SCN_022_R | CF12: H
A13: P012 | B13: תת-אופטימלי ← אופטימלי | C13: עמודות נערמות ← רדאר ← מפת חום | D13: מפת חום ← עמודות נערמות ← רדאר | E13: SCN_001_S | F13: E | G13: SCN_031_S | H13: E | I13: SCN_002_R | J13: E | K13: SCN_032_R | L13: E | M13: SCN_003_H | N13: E | O13: SCN_033_H | P13: E | Q13: SUB | R13: עמודות נערמות ← רדאר ← מפת חום | S13: עמודות נערמות | T13: SCN_005_S | U13: E | V13: SCN_010_S | W13: H | X13: SCN_011_S | Y13: E | Z13: SCN_013_S | AA13: H | AD13: רדאר | AE13: SCN_021_R | AF13: E | AG13: SCN_022_R | AH13: H | AI13: SCN_023_R | AJ13: E | AK13: SCN_029_R | AL13: H | AO13: מפת חום | AP13: SCN_019_H | AQ13: E | AR13: SCN_020_H | AS13: H | AT13: SCN_015_H | AU13: E | AV13: SCN_018_H | AW13: H | AZ13: OPT | BA13: מפת חום ← עמודות נערמות ← רדאר | BB13: מפת חום | BC13: SCN_014_H | BD13: E | BE13: SCN_016_H | BF13: H | BG13: SCN_017_H | BH13: E | BI13: SCN_012_H | BJ13: H | BK13: SCN_025_H | BL13: E | BM13: עמודות נערמות | BN13: SCN_004_S | BO13: E | BP13: SCN_008_S | BQ13: H | BR13: SCN_009_S | BS13: E | BT13: SCN_006_S | BU13: H | BV13: SCN_007_S | BW13: E | BX13: רדאר | BY13: SCN_028_R | BZ13: H | CA13: SCN_027_R | CB13: E | CC13: SCN_026_R | CD13: H | CE13: SCN_030_R | CF13: E | CG13: SCN_024_R | CH13: H
A14: P013 | B14: אופטימלי ← תת-אופטימלי | C14: עמודות נערמות ← רדאר ← מפת חום | D14: רדאר ← מפת חום ← עמודות נערמות | E14: SCN_001_S | F14: E | G14: SCN_031_S | H14: E | I14: SCN_002_R | J14: E | K14: SCN_032_R | L14: E | M14: SCN_003_H | N14: E | O14: SCN_033_H | P14: E | Q14: OPT | R14: עמודות נערמות ← רדאר ← מפת חום | S14: עמודות נערמות | T14: SCN_009_S | U14: E | V14: SCN_006_S | W14: H | X14: SCN_007_S | Y14: E | Z14: SCN_008_S | AA14: H | AB14: SCN_004_S | AC14: E | AD14: רדאר | AE14: SCN_026_R | AF14: H | AG14: SCN_030_R | AH14: E | AI14: SCN_024_R | AJ14: H | AK14: SCN_027_R | AL14: E | AM14: SCN_028_R | AN14: H | AO14: מפת חום | AP14: SCN_017_H | AQ14: E | AR14: SCN_016_H | AS14: H | AT14: SCN_014_H | AU14: E | AV14: SCN_012_H | AW14: H | AX14: SCN_025_H | AY14: E | AZ14: SUB | BA14: רדאר ← מפת חום ← עמודות נערמות | BB14: רדאר | BC14: SCN_021_R | BD14: E | BE14: SCN_022_R | BF14: H | BG14: SCN_023_R | BH14: E | BI14: SCN_029_R | BJ14: H | BM14: מפת חום | BN14: SCN_019_H | BO14: E | BP14: SCN_018_H | BQ14: H | BR14: SCN_015_H | BS14: E | BT14: SCN_020_H | BU14: H | BX14: עמודות נערמות | BY14: SCN_005_S | BZ14: E | CA14: SCN_013_S | CB14: H | CC14: SCN_011_S | CD14: E | CE14: SCN_010_S | CF14: H
A15: P014 | B15: תת-אופטימלי ← אופטימלי | C15: מפת חום ← עמודות נערמות ← רדאר | D15: רדאר ← מפת חום ← עמודות נערמות | E15: SCN_001_S | F15: E | G15: SCN_031_S | H15: E | I15: SCN_002_R | J15: E | K15: SCN_032_R | L15: E | M15: SCN_003_H | N15: E | O15: SCN_033_H | P15: E | Q15: SUB | R15: מפת חום ← עמודות נערמות ← רדאר | S15: מפת חום | T15: SCN_019_H | U15: E | V15: SCN_020_H | W15: H | X15: SCN_015_H | Y15: E | Z15: SCN_018_H | AA15: H | AD15: עמודות נערמות | AE15: SCN_011_S | AF15: E | AG15: SCN_010_S | AH15: H | AI15: SCN_005_S | AJ15: E | AK15: SCN_013_S | AL15: H | AO15: רדאר | AP15: SCN_021_R | AQ15: E | AR15: SCN_029_R | AS15: H | AT15: SCN_023_R | AU15: E | AV15: SCN_022_R | AW15: H | AZ15: OPT | BA15: רדאר ← מפת חום ← עמודות נערמות | BB15: רדאר | BC15: SCN_028_R | BD15: H | BE15: SCN_030_R | BF15: E | BG15: SCN_026_R | BH15: H | BI15: SCN_027_R | BJ15: E | BK15: SCN_024_R | BL15: H | BM15: מפת חום | BN15: SCN_025_H | BO15: E | BP15: SCN_012_H | BQ15: H | BR15: SCN_014_H | BS15: E | BT15: SCN_016_H | BU15: H | BV15: SCN_017_H | BW15: E | BX15: עמודות נערמות | BY15: SCN_007_S | BZ15: E | CA15: SCN_006_S | CB15: H | CC15: SCN_004_S | CD15: E | CE15: SCN_008_S | CF15: H | CG15: SCN_009_S | CH15: E
A16: P015 | B16: אופטימלי ← תת-אופטימלי | C16: מפת חום ← עמודות נערמות ← רדאר | D16: עמודות נערמות ← רדאר ← מפת חום | E16: SCN_001_S | F16: E | G16: SCN_031_S | H16: E | I16: SCN_002_R | J16: E | K16: SCN_032_R | L16: E | M16: SCN_003_H | N16: E | O16: SCN_033_H | P16: E | Q16: OPT | R16: מפת חום ← עמודות נערמות ← רדאר | S16: מפת חום | T16: SCN_025_H | U16: E | V16: SCN_016_H | W16: H | X16: SCN_017_H | Y16: E | Z16: SCN_012_H | AA16: H | AB16: SCN_014_H | AC16: E | AD16: עמודות נערמות | AE16: SCN_004_S | AF16: E | AG16: SCN_006_S | AH16: H | AI16: SCN_009_S | AJ16: E | AK16: SCN_008_S | AL16: H | AM16: SCN_007_S | AN16: E | AO16: רדאר | AP16: SCN_024_R | AQ16: H | AR16: SCN_030_R | AS16: E | AT16: SCN_028_R | AU16: H | AV16: SCN_027_R | AW16: E | AX16: SCN_026_R | AY16: H | AZ16: SUB | BA16: עמודות נערמות ← רדאר ← מפת חום | BB16: עמודות נערמות | BC16: SCN_005_S | BD16: E | BE16: SCN_010_S | BF16: H | BG16: SCN_011_S | BH16: E | BI16: SCN_013_S | BJ16: H | BM16: רדאר | BN16: SCN_021_R | BO16: E | BP16: SCN_029_R | BQ16: H | BR16: SCN_023_R | BS16: E | BT16: SCN_022_R | BU16: H | BX16: מפת חום | BY16: SCN_019_H | BZ16: E | CA16: SCN_020_H | CB16: H | CC16: SCN_015_H | CD16: E | CE16: SCN_018_H | CF16: H
A17: P016 | B17: תת-אופטימלי ← אופטימלי | C17: רדאר ← מפת חום ← עמודות נערמות | D17: עמודות נערמות ← רדאר ← מפת חום | E17: SCN_001_S | F17: E | G17: SCN_031_S | H17: E | I17: SCN_002_R | J17: E | K17: SCN_032_R | L17: E | M17: SCN_003_H | N17: E | O17: SCN_033_H | P17: E | Q17: SUB | R17: רדאר ← מפת חום ← עמודות נערמות | S17: רדאר | T17: SCN_021_R | U17: E | V17: SCN_029_R | W17: H | X17: SCN_023_R | Y17: E | Z17: SCN_022_R | AA17: H | AD17: מפת חום | AE17: SCN_019_H | AF17: E | AG17: SCN_020_H | AH17: H | AI17: SCN_015_H | AJ17: E | AK17: SCN_018_H | AL17: H | AO17: עמודות נערמות | AP17: SCN_011_S | AQ17: E | AR17: SCN_010_S | AS17: H | AT17: SCN_005_S | AU17: E | AV17: SCN_013_S | AW17: H | AZ17: OPT | BA17: עמודות נערמות ← רדאר ← מפת חום | BB17: עמודות נערמות | BC17: SCN_009_S | BD17: E | BE17: SCN_008_S | BF17: H | BG17: SCN_004_S | BH17: E | BI17: SCN_006_S | BJ17: H | BK17: SCN_007_S | BL17: E | BM17: רדאר | BN17: SCN_028_R | BO17: H | BP17: SCN_027_R | BQ17: E | BR17: SCN_024_R | BS17: H | BT17: SCN_030_R | BU17: E | BV17: SCN_026_R | BW17: H | BX17: מפת חום | BY17: SCN_025_H | BZ17: E | CA17: SCN_016_H | CB17: H | CC17: SCN_017_H | CD17: E | CE17: SCN_012_H | CF17: H | CG17: SCN_014_H | CH17: E
A18: P017 | B18: אופטימלי ← תת-אופטימלי | C18: רדאר ← מפת חום ← עמודות נערמות | D18: מפת חום ← עמודות נערמות ← רדאר | E18: SCN_001_S | F18: E | G18: SCN_031_S | H18: E | I18: SCN_002_R | J18: E | K18: SCN_032_R | L18: E | M18: SCN_003_H | N18: E | O18: SCN_033_H | P18: E | Q18: OPT | R18: רדאר ← מפת חום ← עמודות נערמות | S18: רדאר | T18: SCN_028_R | U18: H | V18: SCN_030_R | W18: E | X18: SCN_026_R | Y18: H | Z18: SCN_027_R | AA18: E | AB18: SCN_024_R | AC18: H | AD18: מפת חום | AE18: SCN_025_H | AF18: E | AG18: SCN_012_H | AH18: H | AI18: SCN_014_H | AJ18: E | AK18: SCN_016_H | AL18: H | AM18: SCN_017_H | AN18: E | AO18: עמודות נערמות | AP18: SCN_004_S | AQ18: E | AR18: SCN_006_S | AS18: H | AT18: SCN_007_S | AU18: E | AV18: SCN_008_S | AW18: H | AX18: SCN_009_S | AY18: E | AZ18: SUB | BA18: מפת חום ← עמודות נערמות ← רדאר | BB18: מפת חום | BC18: SCN_019_H | BD18: E | BE18: SCN_020_H | BF18: H | BG18: SCN_015_H | BH18: E | BI18: SCN_018_H | BJ18: H | BM18: עמודות נערמות | BN18: SCN_011_S | BO18: E | BP18: SCN_010_S | BQ18: H | BR18: SCN_005_S | BS18: E | BT18: SCN_013_S | BU18: H | BX18: רדאר | BY18: SCN_021_R | BZ18: E | CA18: SCN_029_R | CB18: H | CC18: SCN_023_R | CD18: E | CE18: SCN_022_R | CF18: H
A19: P018 | B19: תת-אופטימלי ← אופטימלי | C19: עמודות נערמות ← רדאר ← מפת חום | D19: מפת חום ← עמודות נערמות ← רדאר | E19: SCN_001_S | F19: E | G19: SCN_031_S | H19: E | I19: SCN_002_R | J19: E | K19: SCN_032_R | L19: E | M19: SCN_003_H | N19: E | O19: SCN_033_H | P19: E | Q19: SUB | R19: עמודות נערמות ← רדאר ← מפת חום | S19: עמודות נערמות | T19: SCN_011_S | U19: E | V19: SCN_013_S | W19: H | X19: SCN_005_S | Y19: E | Z19: SCN_010_S | AA19: H | AD19: רדאר | AE19: SCN_023_R | AF19: E | AG19: SCN_022_R | AH19: H | AI19: SCN_021_R | AJ19: E | AK19: SCN_029_R | AL19: H | AO19: מפת חום | AP19: SCN_015_H | AQ19: E | AR19: SCN_018_H | AS19: H | AT19: SCN_019_H | AU19: E | AV19: SCN_020_H | AW19: H | AZ19: OPT | BA19: מפת חום ← עמודות נערמות ← רדאר | BB19: מפת חום | BC19: SCN_014_H | BD19: E | BE19: SCN_012_H | BF19: H | BG19: SCN_025_H | BH19: E | BI19: SCN_016_H | BJ19: H | BK19: SCN_017_H | BL19: E | BM19: עמודות נערמות | BN19: SCN_004_S | BO19: E | BP19: SCN_008_S | BQ19: H | BR19: SCN_009_S | BS19: E | BT19: SCN_006_S | BU19: H | BV19: SCN_007_S | BW19: E | BX19: רדאר | BY19: SCN_028_R | BZ19: H | CA19: SCN_030_R | CB19: E | CC19: SCN_024_R | CD19: H | CE19: SCN_027_R | CF19: E | CG19: SCN_026_R | CH19: H
A20: P019 | B20: אופטימלי ← תת-אופטימלי | C20: עמודות נערמות ← רדאר ← מפת חום | D20: רדאר ← מפת חום ← עמודות נערמות | E20: SCN_001_S | F20: E | G20: SCN_031_S | H20: E | I20: SCN_002_R | J20: E | K20: SCN_032_R | L20: E | M20: SCN_003_H | N20: E | O20: SCN_033_H | P20: E | Q20: OPT | R20: עמודות נערמות ← רדאר ← מפת חום | S20: עמודות נערמות | T20: SCN_009_S | U20: E | V20: SCN_006_S | W20: H | X20: SCN_007_S | Y20: E | Z20: SCN_008_S | AA20: H | AB20: SCN_004_S | AC20: E | AD20: רדאר | AE20: SCN_028_R | AF20: H | AG20: SCN_027_R | AH20: E | AI20: SCN_024_R | AJ20: H | AK20: SCN_030_R | AL20: E | AM20: SCN_026_R | AN20: H | AO20: מפת חום | AP20: SCN_017_H | AQ20: E | AR20: SCN_012_H | AS20: H | AT20: SCN_014_H | AU20: E | AV20: SCN_016_H | AW20: H | AX20: SCN_025_H | AY20: E | AZ20: SUB | BA20: רדאר ← מפת חום ← עמודות נערמות | BB20: רדאר | BC20: SCN_021_R | BD20: E | BE20: SCN_022_R | BF20: H | BG20: SCN_023_R | BH20: E | BI20: SCN_029_R | BJ20: H | BM20: מפת חום | BN20: SCN_019_H | BO20: E | BP20: SCN_020_H | BQ20: H | BR20: SCN_015_H | BS20: E | BT20: SCN_018_H | BU20: H | BX20: עמודות נערמות | BY20: SCN_011_S | BZ20: E | CA20: SCN_010_S | CB20: H | CC20: SCN_005_S | CD20: E | CE20: SCN_013_S | CF20: H
A21: P020 | B21: תת-אופטימלי ← אופטימלי | C21: מפת חום ← עמודות נערמות ← רדאר | D21: רדאר ← מפת חום ← עמודות נערמות | E21: SCN_001_S | F21: E | G21: SCN_031_S | H21: E | I21: SCN_002_R | J21: E | K21: SCN_032_R | L21: E | M21: SCN_003_H | N21: E | O21: SCN_033_H | P21: E | Q21: SUB | R21: מפת חום ← עמודות נערמות ← רדאר | S21: מפת חום | T21: SCN_019_H | U21: E | V21: SCN_018_H | W21: H | X21: SCN_015_H | Y21: E | Z21: SCN_020_H | AA21: H | AD21: עמודות נערמות | AE21: SCN_005_S | AF21: E | AG21: SCN_010_S | AH21: H | AI21: SCN_011_S | AJ21: E | AK21: SCN_013_S | AL21: H | AO21: רדאר | AP21: SCN_023_R | AQ21: E | AR21: SCN_022_R | AS21: H | AT21: SCN_021_R | AU21: E | AV21: SCN_029_R | AW21: H | AZ21: OPT | BA21: רדאר ← מפת חום ← עמודות נערמות | BB21: רדאר | BC21: SCN_024_R | BD21: H | BE21: SCN_027_R | BF21: E | BG21: SCN_026_R | BH21: H | BI21: SCN_030_R | BJ21: E | BK21: SCN_028_R | BL21: H | BM21: מפת חום | BN21: SCN_017_H | BO21: E | BP21: SCN_016_H | BQ21: H | BR21: SCN_025_H | BS21: E | BT21: SCN_012_H | BU21: H | BV21: SCN_014_H | BW21: E | BX21: עמודות נערמות | BY21: SCN_004_S | BZ21: E | CA21: SCN_008_S | CB21: H | CC21: SCN_007_S | CD21: E | CE21: SCN_006_S | CF21: H | CG21: SCN_009_S | CH21: E
A22: P021 | B22: אופטימלי ← תת-אופטימלי | C22: מפת חום ← עמודות נערמות ← רדאר | D22: עמודות נערמות ← רדאר ← מפת חום | E22: SCN_001_S | F22: E | G22: SCN_031_S | H22: E | I22: SCN_002_R | J22: E | K22: SCN_032_R | L22: E | M22: SCN_003_H | N22: E | O22: SCN_033_H | P22: E | Q22: OPT | R22: מפת חום ← עמודות נערמות ← רדאר | S22: מפת חום | T22: SCN_024_H | U22: H | V22: SCN_030_H | W22: E | X22: SCN_028_H | Y22: H | Z22: SCN_027_H | AA22: E | AB22: SCN_026_H | AC22: H | AD22: עמודות נערמות | AE22: SCN_025_S | AF22: E | AG22: SCN_016_S | AH22: H | AI22: SCN_014_S | AJ22: E | AK22: SCN_012_S | AL22: H | AM22: SCN_017_S | AN22: E | AO22: רדאר | AP22: SCN_009_R | AQ22: E | AR22: SCN_006_R | AS22: H | AT22: SCN_004_R | AU22: E | AV22: SCN_008_R | AW22: H | AX22: SCN_007_R | AY22: E | AZ22: SUB | BA22: עמודות נערמות ← רדאר ← מפת חום | BB22: עמודות נערמות | BC22: SCN_015_S | BD22: E | BE22: SCN_020_S | BF22: H | BG22: SCN_019_S | BH22: E | BI22: SCN_018_S | BJ22: H | BM22: רדאר | BN22: SCN_011_R | BO22: E | BP22: SCN_010_R | BQ22: H | BR22: SCN_005_R | BS22: E | BT22: SCN_013_R | BU22: H | BX22: מפת חום | BY22: SCN_023_H | BZ22: E | CA22: SCN_022_H | CB22: H | CC22: SCN_021_H | CD22: E | CE22: SCN_029_H | CF22: H
A23: P022 | B23: תת-אופטימלי ← אופטימלי | C23: רדאר ← מפת חום ← עמודות נערמות | D23: עמודות נערמות ← רדאר ← מפת חום | E23: SCN_001_S | F23: E | G23: SCN_031_S | H23: E | I23: SCN_002_R | J23: E | K23: SCN_032_R | L23: E | M23: SCN_003_H | N23: E | O23: SCN_033_H | P23: E | Q23: SUB | R23: רדאר ← מפת חום ← עמודות נערמות | S23: רדאר | T23: SCN_005_R | U23: E | V23: SCN_013_R | W23: H | X23: SCN_011_R | Y23: E | Z23: SCN_010_R | AA23: H | AD23: מפת חום | AE23: SCN_021_H | AF23: E | AG23: SCN_029_H | AH23: H | AI23: SCN_023_H | AJ23: E | AK23: SCN_022_H | AL23: H | AO23: עמודות נערמות | AP23: SCN_015_S | AQ23: E | AR23: SCN_020_S | AS23: H | AT23: SCN_019_S | AU23: E | AV23: SCN_018_S | AW23: H | AZ23: OPT | BA23: עמודות נערמות ← רדאר ← מפת חום | BB23: עמודות נערמות | BC23: SCN_017_S | BD23: E | BE23: SCN_012_S | BF23: H | BG23: SCN_025_S | BH23: E | BI23: SCN_016_S | BJ23: H | BK23: SCN_014_S | BL23: E | BM23: רדאר | BN23: SCN_007_R | BO23: E | BP23: SCN_008_R | BQ23: H | BR23: SCN_009_R | BS23: E | BT23: SCN_006_R | BU23: H | BV23: SCN_004_R | BW23: E | BX23: מפת חום | BY23: SCN_028_H | BZ23: H | CA23: SCN_030_H | CB23: E | CC23: SCN_026_H | CD23: H | CE23: SCN_027_H | CF23: E | CG23: SCN_024_H | CH23: H
A24: P023 | B24: אופטימלי ← תת-אופטימלי | C24: רדאר ← מפת חום ← עמודות נערמות | D24: מפת חום ← עמודות נערמות ← רדאר | E24: SCN_001_S | F24: E | G24: SCN_031_S | H24: E | I24: SCN_002_R | J24: E | K24: SCN_032_R | L24: E | M24: SCN_003_H | N24: E | O24: SCN_033_H | P24: E | Q24: OPT | R24: רדאר ← מפת חום ← עמודות נערמות | S24: רדאר | T24: SCN_004_R | U24: E | V24: SCN_008_R | W24: H | X24: SCN_007_R | Y24: E | Z24: SCN_006_R | AA24: H | AB24: SCN_009_R | AC24: E | AD24: מפת חום | AE24: SCN_028_H | AF24: H | AG24: SCN_027_H | AH24: E | AI24: SCN_026_H | AJ24: H | AK24: SCN_030_H | AL24: E | AM24: SCN_024_H | AN24: H | AO24: עמודות נערמות | AP24: SCN_025_S | AQ24: E | AR24: SCN_016_S | AS24: H | AT24: SCN_014_S | AU24: E | AV24: SCN_012_S | AW24: H | AX24: SCN_017_S | AY24: E | AZ24: SUB | BA24: מפת חום ← עמודות נערמות ← רדאר | BB24: מפת חום | BC24: SCN_023_H | BD24: E | BE24: SCN_029_H | BF24: H | BG24: SCN_021_H | BH24: E | BI24: SCN_022_H | BJ24: H | BM24: עמודות נערמות | BN24: SCN_019_S | BO24: E | BP24: SCN_018_S | BQ24: H | BR24: SCN_015_S | BS24: E | BT24: SCN_020_S | BU24: H | BX24: רדאר | BY24: SCN_005_R | BZ24: E | CA24: SCN_013_R | CB24: H | CC24: SCN_011_R | CD24: E | CE24: SCN_010_R | CF24: H
A25: P024 | B25: תת-אופטימלי ← אופטימלי | C25: עמודות נערמות ← רדאר ← מפת חום | D25: מפת חום ← עמודות נערמות ← רדאר | E25: SCN_001_S | F25: E | G25: SCN_031_S | H25: E | I25: SCN_002_R | J25: E | K25: SCN_032_R | L25: E | M25: SCN_003_H | N25: E | O25: SCN_033_H | P25: E | Q25: SUB | R25: עמודות נערמות ← רדאר ← מפת חום | S25: עמודות נערמות | T25: SCN_015_S | U25: E | V25: SCN_020_S | W25: H | X25: SCN_019_S | Y25: E | Z25: SCN_018_S | AA25: H | AD25: רדאר | AE25: SCN_005_R | AF25: E | AG25: SCN_010_R | AH25: H | AI25: SCN_011_R | AJ25: E | AK25: SCN_013_R | AL25: H | AO25: מפת חום | AP25: SCN_023_H | AQ25: E | AR25: SCN_022_H | AS25: H | AT25: SCN_021_H | AU25: E | AV25: SCN_029_H | AW25: H | AZ25: OPT | BA25: מפת חום ← עמודות נערמות ← רדאר | BB25: מפת חום | BC25: SCN_026_H | BD25: H | BE25: SCN_027_H | BF25: E | BG25: SCN_024_H | BH25: H | BI25: SCN_030_H | BJ25: E | BK25: SCN_028_H | BL25: H | BM25: עמודות נערמות | BN25: SCN_025_S | BO25: E | BP25: SCN_012_S | BQ25: H | BR25: SCN_014_S | BS25: E | BT25: SCN_016_S | BU25: H | BV25: SCN_017_S | BW25: E | BX25: רדאר | BY25: SCN_004_R | BZ25: E | CA25: SCN_008_R | CB25: H | CC25: SCN_009_R | CD25: E | CE25: SCN_006_R | CF25: H | CG25: SCN_007_R | CH25: E
A26: P025 | B26: אופטימלי ← תת-אופטימלי | C26: עמודות נערמות ← רדאר ← מפת חום | D26: רדאר ← מפת חום ← עמודות נערמות | E26: SCN_001_S | F26: E | G26: SCN_031_S | H26: E | I26: SCN_002_R | J26: E | K26: SCN_032_R | L26: E | M26: SCN_003_H | N26: E | O26: SCN_033_H | P26: E | Q26: OPT | R26: עמודות נערמות ← רדאר ← מפת חום | S26: עמודות נערמות | T26: SCN_025_S | U26: E | V26: SCN_016_S | W26: H | X26: SCN_014_S | Y26: E | Z26: SCN_012_S | AA26: H | AB26: SCN_017_S | AC26: E | AD26: רדאר | AE26: SCN_009_R | AF26: E | AG26: SCN_006_R | AH26: H | AI26: SCN_007_R | AJ26: E | AK26: SCN_008_R | AL26: H | AM26: SCN_004_R | AN26: E | AO26: מפת חום | AP26: SCN_028_H | AQ26: H | AR26: SCN_030_H | AS26: E | AT26: SCN_026_H | AU26: H | AV26: SCN_027_H | AW26: E | AX26: SCN_024_H | AY26: H | AZ26: SUB | BA26: רדאר ← מפת חום ← עמודות נערמות | BB26: רדאר | BC26: SCN_005_R | BD26: E | BE26: SCN_013_R | BF26: H | BG26: SCN_011_R | BH26: E | BI26: SCN_010_R | BJ26: H | BM26: מפת חום | BN26: SCN_021_H | BO26: E | BP26: SCN_022_H | BQ26: H | BR26: SCN_023_H | BS26: E | BT26: SCN_029_H | BU26: H | BX26: עמודות נערמות | BY26: SCN_015_S | BZ26: E | CA26: SCN_020_S | CB26: H | CC26: SCN_019_S | CD26: E | CE26: SCN_018_S | CF26: H
A27: P026 | B27: תת-אופטימלי ← אופטימלי | C27: מפת חום ← עמודות נערמות ← רדאר | D27: רדאר ← מפת חום ← עמודות נערמות | E27: SCN_001_S | F27: E | G27: SCN_031_S | H27: E | I27: SCN_002_R | J27: E | K27: SCN_032_R | L27: E | M27: SCN_003_H | N27: E | O27: SCN_033_H | P27: E | Q27: SUB | R27: מפת חום ← עמודות נערמות ← רדאר | S27: מפת חום | T27: SCN_021_H | U27: E | V27: SCN_029_H | W27: H | X27: SCN_023_H | Y27: E | Z27: SCN_022_H | AA27: H | AD27: עמודות נערמות | AE27: SCN_019_S | AF27: E | AG27: SCN_020_S | AH27: H | AI27: SCN_015_S | AJ27: E | AK27: SCN_018_S | AL27: H | AO27: רדאר | AP27: SCN_011_R | AQ27: E | AR27: SCN_013_R | AS27: H | AT27: SCN_005_R | AU27: E | AV27: SCN_010_R | AW27: H | AZ27: OPT | BA27: רדאר ← מפת חום ← עמודות נערמות | BB27: רדאר | BC27: SCN_009_R | BD27: E | BE27: SCN_008_R | BF27: H | BG27: SCN_004_R | BH27: E | BI27: SCN_006_R | BJ27: H | BK27: SCN_007_R | BL27: E | BM27: מפת חום | BN27: SCN_024_H | BO27: H | BP27: SCN_027_H | BQ27: E | BR27: SCN_028_H | BS27: H | BT27: SCN_030_H | BU27: E | BV27: SCN_026_H | BW27: H | BX27: עמודות נערמות | BY27: SCN_014_S | BZ27: E | CA27: SCN_016_S | CB27: H | CC27: SCN_025_S | CD27: E | CE27: SCN_012_S | CF27: H | CG27: SCN_017_S | CH27: E
A28: P027 | B28: אופטימלי ← תת-אופטימלי | C28: מפת חום ← עמודות נערמות ← רדאר | D28: עמודות נערמות ← רדאר ← מפת חום | E28: SCN_001_S | F28: E | G28: SCN_031_S | H28: E | I28: SCN_002_R | J28: E | K28: SCN_032_R | L28: E | M28: SCN_003_H | N28: E | O28: SCN_033_H | P28: E | Q28: OPT | R28: מפת חום ← עמודות נערמות ← רדאר | S28: מפת חום | T28: SCN_026_H | U28: H | V28: SCN_030_H | W28: E | X28: SCN_028_H | Y28: H | Z28: SCN_027_H | AA28: E | AB28: SCN_024_H | AC28: H | AD28: עמודות נערמות | AE28: SCN_014_S | AF28: E | AG28: SCN_012_S | AH28: H | AI28: SCN_025_S | AJ28: E | AK28: SCN_016_S | AL28: H | AM28: SCN_017_S | AN28: E | AO28: רדאר | AP28: SCN_007_R | AQ28: E | AR28: SCN_008_R | AS28: H | AT28: SCN_009_R | AU28: E | AV28: SCN_006_R | AW28: H | AX28: SCN_004_R | AY28: E | AZ28: SUB | BA28: עמודות נערמות ← רדאר ← מפת חום | BB28: עמודות נערמות | BC28: SCN_019_S | BD28: E | BE28: SCN_020_S | BF28: H | BG28: SCN_015_S | BH28: E | BI28: SCN_018_S | BJ28: H | BM28: רדאר | BN28: SCN_011_R | BO28: E | BP28: SCN_010_R | BQ28: H | BR28: SCN_005_R | BS28: E | BT28: SCN_013_R | BU28: H | BX28: מפת חום | BY28: SCN_021_H | BZ28: E | CA28: SCN_029_H | CB28: H | CC28: SCN_023_H | CD28: E | CE28: SCN_022_H | CF28: H
A29: P028 | B29: תת-אופטימלי ← אופטימלי | C29: רדאר ← מפת חום ← עמודות נערמות | D29: עמודות נערמות ← רדאר ← מפת חום | E29: SCN_001_S | F29: E | G29: SCN_031_S | H29: E | I29: SCN_002_R | J29: E | K29: SCN_032_R | L29: E | M29: SCN_003_H | N29: E | O29: SCN_033_H | P29: E | Q29: SUB | R29: רדאר ← מפת חום ← עמודות נערמות | S29: רדאר | T29: SCN_005_R | U29: E | V29: SCN_013_R | W29: H | X29: SCN_011_R | Y29: E | Z29: SCN_010_R | AA29: H | AD29: מפת חום | AE29: SCN_021_H | AF29: E | AG29: SCN_029_H | AH29: H | AI29: SCN_023_H | AJ29: E | AK29: SCN_022_H | AL29: H | AO29: עמודות נערמות | AP29: SCN_019_S | AQ29: E | AR29: SCN_018_S | AS29: H | AT29: SCN_015_S | AU29: E | AV29: SCN_020_S | AW29: H | AZ29: OPT | BA29: עמודות נערמות ← רדאר ← מפת חום | BB29: עמודות נערמות | BC29: SCN_017_S | BD29: E | BE29: SCN_012_S | BF29: H | BG29: SCN_025_S | BH29: E | BI29: SCN_016_S | BJ29: H | BK29: SCN_014_S | BL29: E | BM29: רדאר | BN29: SCN_004_R | BO29: E | BP29: SCN_006_R | BQ29: H | BR29: SCN_007_R | BS29: E | BT29: SCN_008_R | BU29: H | BV29: SCN_009_R | BW29: E | BX29: מפת חום | BY29: SCN_026_H | BZ29: H | CA29: SCN_030_H | CB29: E | CC29: SCN_028_H | CD29: H | CE29: SCN_027_H | CF29: E | CG29: SCN_024_H | CH29: H
A30: P029 | B30: אופטימלי ← תת-אופטימלי | C30: רדאר ← מפת חום ← עמודות נערמות | D30: מפת חום ← עמודות נערמות ← רדאר | E30: SCN_001_S | F30: E | G30: SCN_031_S | H30: E | I30: SCN_002_R | J30: E | K30: SCN_032_R | L30: E | M30: SCN_003_H | N30: E | O30: SCN_033_H | P30: E | Q30: OPT | R30: רדאר ← מפת חום ← עמודות נערמות | S30: רדאר | T30: SCN_004_R | U30: E | V30: SCN_006_R | W30: H | X30: SCN_009_R | Y30: E | Z30: SCN_008_R | AA30: H | AB30: SCN_007_R | AC30: E | AD30: מפת חום | AE30: SCN_028_H | AF30: H | AG30: SCN_030_H | AH30: E | AI30: SCN_024_H | AJ30: H | AK30: SCN_027_H | AL30: E | AM30: SCN_026_H | AN30: H | AO30: עמודות נערמות | AP30: SCN_017_S | AQ30: E | AR30: SCN_012_S | AS30: H | AT30: SCN_025_S | AU30: E | AV30: SCN_016_S | AW30: H | AX30: SCN_014_S | AY30: E | AZ30: SUB | BA30: מפת חום ← עמודות נערמות ← רדאר | BB30: מפת חום | BC30: SCN_021_H | BD30: E | BE30: SCN_029_H | BF30: H | BG30: SCN_023_H | BH30: E | BI30: SCN_022_H | BJ30: H | BM30: עמודות נערמות | BN30: SCN_019_S | BO30: E | BP30: SCN_020_S | BQ30: H | BR30: SCN_015_S | BS30: E | BT30: SCN_018_S | BU30: H | BX30: רדאר | BY30: SCN_005_R | BZ30: E | CA30: SCN_010_R | CB30: H | CC30: SCN_011_R | CD30: E | CE30: SCN_013_R | CF30: H
A31: P030 | B31: תת-אופטימלי ← אופטימלי | C31: עמודות נערמות ← רדאר ← מפת חום | D31: מפת חום ← עמודות נערמות ← רדאר | E31: SCN_001_S | F31: E | G31: SCN_031_S | H31: E | I31: SCN_002_R | J31: E | K31: SCN_032_R | L31: E | M31: SCN_003_H | N31: E | O31: SCN_033_H | P31: E | Q31: SUB | R31: עמודות נערמות ← רדאר ← מפת חום | S31: עמודות נערמות | T31: SCN_015_S | U31: E | V31: SCN_020_S | W31: H | X31: SCN_019_S | Y31: E | Z31: SCN_018_S | AA31: H | AD31: רדאר | AE31: SCN_011_R | AF31: E | AG31: SCN_013_R | AH31: H | AI31: SCN_005_R | AJ31: E | AK31: SCN_010_R | AL31: H | AO31: מפת חום | AP31: SCN_021_H | AQ31: E | AR31: SCN_022_H | AS31: H | AT31: SCN_023_H | AU31: E | AV31: SCN_029_H | AW31: H | AZ31: OPT | BA31: מפת חום ← עמודות נערמות ← רדאר | BB31: מפת חום | BC31: SCN_026_H | BD31: H | BE31: SCN_027_H | BF31: E | BG31: SCN_028_H | BH31: H | BI31: SCN_030_H | BJ31: E | BK31: SCN_024_H | BL31: H | BM31: עמודות נערמות | BN31: SCN_014_S | BO31: E | BP31: SCN_012_S | BQ31: H | BR31: SCN_017_S | BS31: E | BT31: SCN_016_S | BU31: H | BV31: SCN_025_S | BW31: E | BX31: רדאר | BY31: SCN_007_R | BZ31: E | CA31: SCN_008_R | CB31: H | CC31: SCN_009_R | CD31: E | CE31: SCN_006_R | CF31: H | CG31: SCN_004_R | CH31: E

Sheet קטלוג תרחישים
A1: SCN_ID | B1: יישוב | C1: Scenario_ID_H | D1: Scenario_ID_R | E1: Scenario_ID_S | F1: TRAFFIC | G1: TOLL | H1: COMM | I1: Route_Direction | J1: Practice | K1: Base_Difficulty | L1: CORRECT_ROUTE | M1: REC_INACCURATE | N1: Q1 | O1: O1 | P1: A1 | Q1: Q2 | R1: O2 | S1: A2 | T1: Q3 | U1: O3 | V1: A3 | W1: TASK_TEXT | X1: Priority | Y1: SEG | Z1: SEG_PRIORITY | AA1: REQUIREMENTS | AB1: Status | AN1: O1 | AO1: A1 | AP1: Q2 | AQ1: O2 | AR1: A2
A2: SCN_001 | B2: ראש העין | C2: =A2&"_H" -> SCN_001_H | D2: =A2&"_R" -> SCN_001_R | E2: =A2&"_S" -> SCN_001_S | F2: 1 | G2: 1 | H2: 1 | I2: RTL | J2: Y | K2: E | L2: א' | M2: ב' | N2: לפי הוויזואליזציה (בפאנל התחתון) איזה מסלול הציג את הציונים הגבוהים ביותר בקטגוריית קליטה? | O2: מסלול א מסלול ב מסלול ג לא יודע/ת | P2: מסלול ג | Q2: לפי הוויזואליזציה (בפאנל התחתון) איזה מסלול הציג את הציונים הגבוהים ביותר בקטגוריית חיסכון? | R2: מסלול א מסלול ב מסלול ג לא יודע/ת | S2: מסלול א | W2: במפה שלפניך מופיעים 3 מסלולים אפשריים בין נקודת המוצא ליעד. בחר ואשר את המסלול שמתעדף את הדרישות: | X2: נוף | AA2: נוף לאורך כל המקטעים במסלול. | AB2: TRUE | AE2: =IF(L2="א'",IF(RANDBETWEEN(0,1)=0,"ב'","ג'"),IF(M2="ב'",IF(RANDBETWEEN(0,1)=0,"א'","ג'"),IF(RANDBETWEEN(0,1)=0,"א'","ב'"))) -> ג' | AH2: =COUNTIF('קטלוג תרחישים'!$I$2:$I$34,"RTL") -> 16 | AI2: RTL
A3: SCN_002 | B3: שדרות | C3: =A3&"_H" -> SCN_002_H | D3: =A3&"_R" -> SCN_002_R | E3: =A3&"_S" -> SCN_002_S | F3: 2 | G3: 1 | H3: 1 | I3: LTR | J3: Y | K3: E | L3: א' | M3: ג' | N3: לפי הוויזואליזציה (בפאנל התחתון) איזה מסלול הציג את הציונים הגבוהים ביותר בקטגוריית נוף? | O3: מסלול א מסלול ב מסלול ג לא יודע/ת | P3: מסלול ג | Q3: לפי הוויזואליזציה (בפאנל התחתון) איזה מסלול הציג את הציונים הגבוהים ביותר בקטגוריית חיסכון? | R3: מסלול א מסלול ב מסלול ג לא יודע/ת | S3: מסלול ב | W3: במפה שלפניך מופיעים 3 מסלולים אפשריים בין נקודת המוצא ליעד. בחר ואשר את המסלול שמתעדף את הדרישות: | X3: קליטה | AA3: קליטה לאורך כל המקטעים במסלול. | AB3: TRUE | AE3: =IF(L3="א'",IF(RANDBETWEEN(0,1)=0,"ב'","ג'"),IF(M3="ב'",IF(RANDBETWEEN(0,1)=0,"א'","ג'"),IF(RANDBETWEEN(0,1)=0,"א'","ב'"))) -> ב' | AH3: =COUNTIF('קטלוג תרחישים'!$I$2:$I$34,"LTR") -> 17 | AI3: LTR
A4: SCN_003 | B4: רעננה | C4: =A4&"_H" -> SCN_003_H | D4: =A4&"_R" -> SCN_003_R | E4: =A4&"_S" -> SCN_003_S | F4: 3 | G4: 2 | H4: 1 | I4: LTR | J4: Y | K4: E | L4: ב' | M4: ג' | N4: לפי הוויזואליזציה (בפאנל התחתון) איזה מסלול הציג את הציונים הגבוהים ביותר בקטגוריית נוף? | O4: מסלול א מסלול ב מסלול ג לא יודע/ת | P4: מסלול ב | Q4: לפי הוויזואליזציה (בפאנל התחתון) איזה מסלול הציג את הציונים הנמוכים ביותר בקטגוריית קליטה? | R4: מסלול א מסלול ב מסלול ג לא יודע/ת | S4: מסלול א | W4: במפה שלפניך מופיעים 3 מסלולים אפשריים בין נקודת המוצא ליעד. בחר ואשר את המסלול שמתעדף את הדרישות: | X4: חיסכון | AA4: חיסכון לאורך כל המקטעים במסלול. | AB4: TRUE | AE4: =IF(L4="א'",IF(RANDBETWEEN(0,1)=0,"ב'","ג'"),IF(M4="ב'",IF(RANDBETWEEN(0,1)=0,"א'","ג'"),IF(RANDBETWEEN(0,1)=0,"א'","ב'"))) -> ב'
A5: SCN_004 | B5: רמלה | C5: =A5&"_H" -> SCN_004_H | D5: =A5&"_R" -> SCN_004_R | E5: =A5&"_S" -> SCN_004_S | F5: 2 | G5: 2 | H5: 2 | I5: RTL | J5: N | K5: E | L5: ג' | M5: ב' | N5: לפי הוויזואליזציה (בפאנל התחתון) איזה מסלול הציג את הציונים הנמוכים ביותר בקטגוריית חיסכון? | O5: מסלול א מסלול ב מסלול ג לא יודע/ת | P5: מסלול א, מסלול ב | Q5: לפי הוויזואליזציה (בפאנל התחתון) איזה מסלול הציג את הציונים הנמוכים ביותר בקטגוריית קליטה? | R5: מסלול א מסלול ב מסלול ג לא יודע/ת | S5: מסלול א | W5: במפה שלפניך מופיעים 3 מסלולים אפשריים בין נקודת המוצא ליעד. בחר ואשר את המסלול שמתעדף את הדרישות: | X5: קליטה | AA5: קליטה לאורך כל המקטעים במסלול. | AB5: TRUE | AE5: =IF(L5="א'",IF(RANDBETWEEN(0,1)=0,"ב'","ג'"),IF(M5="ב'",IF(RANDBETWEEN(0,1)=0,"א'","ג'"),IF(RANDBETWEEN(0,1)=0,"א'","ב'"))) -> ג' | AH5: =AVERAGE('קטלוג תרחישים'!$H$2:$H$34) -> 1.5757576 | AI5: COMM
A6: SCN_005 | B6: תל מונד | C6: =A6&"_H" -> SCN_005_H | D6: =A6&"_R" -> SCN_005_R | E6: =A6&"_S" -> SCN_005_S | F6: 2 | G6: 1 | H6: 3 | I6: RTL | J6: N | K6: E | L6: ג' | M6: א' | N6: לפי הוויזואליזציה (בפאנל התחתון) איזה מסלול הציג את הציונים הנמוכים ביותר בקטגוריית חיסכון? | O6: מסלול א מסלול ב מסלול ג לא יודע/ת | P6: מסלול א | Q6: לפי הוויזואליזציה (בפאנל התחתון) איזה מסלול הציג את הציונים הנמוכים ביותר בקטגוריית נוף? | R6: מסלול א מסלול ב מסלול ג לא יודע/ת | S6: מסלול ב | W6: במפה שלפניך מופיעים 3 מסלולים אפשריים בין נקודת המוצא ליעד. בחר ואשר את המסלול שמתעדף את הדרישות: | X6: קליטה | AA6: קליטה לאורך כל המקטעים במסלול. | AB6: TRUE | AE6: =IF(L6="א'",IF(RANDBETWEEN(0,1)=0,"ב'","ג'"),IF(M6="ב'",IF(RANDBETWEEN(0,1)=0,"א'","ג'"),IF(RANDBETWEEN(0,1)=0,"א'","ב'"))) -> א' | AH6: =AVERAGE('קטלוג תרחישים'!$G$2:$G$34) -> 1.3939394 | AI6: TOLL
A7: SCN_006 | B7: אור עקיבא | C7: =A7&"_H" -> SCN_006_H | D7: =A7&"_R" -> SCN_006_R | E7: =A7&"_S" -> SCN_006_S | F7: 2 | G7: 1 | H7: 1 | I7: RTL | J7: N | K7: H | L7: ג' | M7: ב' | N7: לפי הוויזואליזציה (בפאנל התחתון) איזה מסלול הציג את הציונים הגבוהים ביותר בקטגוריית קליטה? | O7: מסלול א מסלול ב מסלול ג לא יודע/ת | P7: מסלול א, מסלול ג | Q7: לפי הוויזואליזציה (בפאנל התחתון) איזה מסלול הציג את הציונים הנמוכים ביותר בקטגוריית נוף? | R7: מסלול א מסלול ב מסלול ג לא יודע/ת | S7: מסלול א, מסלול ב | W7: במפה שלפניך מופיעים 3 מסלולים אפשריים בין נקודת המוצא ליעד. בחר ואשר את המסלול שמתעדף את הדרישות: | X7: נוף | Y7: 1 | Z7: חיסכון | AA7: נוף לאורך כל המקטעים במסלול. במקטע 1 גם חיסכון. | AB7: TRUE | AE7: =IF(L7="א'",IF(RANDBETWEEN(0,1)=0,"ב'","ג'"),IF(M7="ב'",IF(RANDBETWEEN(0,1)=0,"א'","ג'"),IF(RANDBETWEEN(0,1)=0,"א'","ב'"))) -> ג' | AF7: קשה | AH7: =AVERAGE('קטלוג תרחישים'!$F$2:$F$34) -> 1.9090909 | AI7: TRAFF
A8: SCN_007 | B8: אשדוד | C8: =A8&"_H" -> SCN_007_H | D8: =A8&"_R" -> SCN_007_R | E8: =A8&"_S" -> SCN_007_S | F8: 2 | G8: 1 | H8: 3 | I8: LTR | J8: N | K8: E | L8: ב' | M8: א' | N8: לפי הוויזואליזציה (בפאנל התחתון) איזה מסלול הציג את הציונים הגבוהים ביותר בקטגוריית קליטה? | O8: מסלול א מסלול ב מסלול ג לא יודע/ת | P8: מסלול ג | Q8: לפי הוויזואליזציה (בפאנל התחתון) איזה מסלול הציג את הציונים הגבוהים ביותר בקטגוריית חיסכון? | R8: מסלול א מסלול ב מסלול ג לא יודע/ת | S8: מסלול ב, מסלול ג | W8: במפה שלפניך מופיעים 3 מסלולים אפשריים בין נקודת המוצא ליעד. בחר ואשר את המסלול שמתעדף את הדרישות: | X8: חיסכון | AA8: חיסכון לאורך כל המקטעים במסלול. | AB8: TRUE | AE8: =IF(L8="א'",IF(RANDBETWEEN(0,1)=0,"ב'","ג'"),IF(M8="ב'",IF(RANDBETWEEN(0,1)=0,"א'","ג'"),IF(RANDBETWEEN(0,1)=0,"א'","ב'"))) -> ב'
A9: SCN_008 | B9: באר שבע צפון | C9: =A9&"_H" -> SCN_008_H | D9: =A9&"_R" -> SCN_008_R | E9: =A9&"_S" -> SCN_008_S | F9: 1 | G9: 2 | H9: 1 | I9: RTL | J9: N | K9: H | L9: א' | M9: ג' | N9: לפי הוויזואליזציה (בפאנל התחתון) איזה מסלול הציג את הציונים הגבוהים ביותר בקטגוריית נוף? | O9: מסלול א מסלול ב מסלול ג לא יודע/ת | P9: מסלול א | Q9: לפי הוויזואליזציה (בפאנל התחתון) איזה מסלול הציג את הציונים הגבוהים ביותר בקטגוריית חיסכון? | R9: מסלול א מסלול ב מסלול ג לא יודע/ת | S9: מסלול ג | W9: במפה שלפניך מופיעים 3 מסלולים אפשריים בין נקודת המוצא ליעד. בחר ואשר את המסלול שמתעדף את הדרישות: | X9: קליטה | Y9: 2 | Z9: נוף | AA9: קליטה לאורך כל המקטעים במסלול. במקטע 2 גם נוף. | AB9: TRUE | AE9: =IF(L9="א'",IF(RANDBETWEEN(0,1)=0,"ב'","ג'"),IF(M9="ב'",IF(RANDBETWEEN(0,1)=0,"א'","ג'"),IF(RANDBETWEEN(0,1)=0,"א'","ב'"))) -> ג' | AH9: =COUNTIF('קטלוג תרחישים'!$AB$2:$AB$34,TRUE) -> 33 | AI9: TOT
A10: SCN_009 | B10: הדר יוסף | C10: =A10&"_H" -> SCN_009_H | D10: =A10&"_R" -> SCN_009_R | E10: =A10&"_S" -> SCN_009_S | F10: 2 | G10: 2 | H10: 2 | I10: LTR | J10: N | K10: E | L10: ג' | M10: ב' | N10: לפי הוויזואליזציה (בפאנל התחתון) איזה מסלול הציג את הציונים הגבוהים ביותר בקטגוריית נוף? | O10: מסלול א מסלול ב מסלול ג לא יודע/ת | P10: מסלול ג | Q10: לפי הוויזואליזציה (בפאנל התחתון) איזה מסלול הציג את הציונים הנמוכים ביותר בקטגוריית קליטה? | R10: מסלול א מסלול ב מסלול ג לא יודע/ת | S10: מסלול א | W10: במפה שלפניך מופיעים 3 מסלולים אפשריים בין נקודת המוצא ליעד. בחר ואשר את המסלול שמתעדף את הדרישות: | X10: נוף | AA10: נוף לאורך כל המקטעים במסלול. | AB10: TRUE | AE10: =IF(L10="א'",IF(RANDBETWEEN(0,1)=0,"ב'","ג'"),IF(M10="ב'",IF(RANDBETWEEN(0,1)=0,"א'","ג'"),IF(RANDBETWEEN(0,1)=0,"א'","ב'"))) -> א'
A11: SCN_010 | B11: דימונה | C11: =A11&"_H" -> SCN_010_H | D11: =A11&"_R" -> SCN_010_R | E11: =A11&"_S" -> SCN_010_S | F11: 2 | G11: 1 | H11: 3 | I11: RTL | J11: N | K11: H | L11: ג' | M11: ב' | N11: לפי הוויזואליזציה (בפאנל התחתון) איזה מסלול הציג את הציונים הנמוכים ביותר בקטגוריית חיסכון? | O11: מסלול א מסלול ב מסלול ג לא יודע/ת | P11: מסלול ב | Q11: לפי הוויזואליזציה (בפאנל התחתון) איזה מסלול הציג את הציונים הנמוכים ביותר בקטגוריית קליטה? | R11: מסלול א מסלול ב מסלול ג לא יודע/ת | S11: מסלול א, מסלול ב | W11: במפה שלפניך מופיעים 3 מסלולים אפשריים בין נקודת המוצא ליעד. בחר ואשר את המסלול שמתעדף את הדרישות: | X11: חיסכון | Y11: 3 | Z11: נוף | AA11: חיסכון לאורך כל המקטעים במסלול. במקטע 3 גם נוף. | AB11: TRUE | AE11: =IF(L11="א'",IF(RANDBETWEEN(0,1)=0,"ב'","ג'"),IF(M11="ב'",IF(RANDBETWEEN(0,1)=0,"א'","ג'"),IF(RANDBETWEEN(0,1)=0,"א'","ב'"))) -> א'
A12: SCN_011 | B12: אשקלון | C12: =A12&"_H" -> SCN_011_H | D12: =A12&"_R" -> SCN_011_R | E12: =A12&"_S" -> SCN_011_S | F12: 2 | G12: 1 | H12: 2 | I12: RTL | J12: N | K12: E | L12: ב' | M12: א' | N12: לפי הוויזואליזציה (בפאנל התחתון) איזה מסלול הציג את הציונים הנמוכים ביותר בקטגוריית חיסכון? | O12: מסלול א מסלול ב מסלול ג לא יודע/ת | P12: מסלול א | Q12: לפי הוויזואליזציה (בפאנל התחתון) איזה מסלול הציג את הציונים הנמוכים ביותר בקטגוריית נוף? | R12: מסלול א מסלול ב מסלול ג לא יודע/ת | S12: מסלול ב | W12: במפה שלפניך מופיעים 3 מסלולים אפשריים בין נקודת המוצא ליעד. בחר ואשר את המסלול שמתעדף את הדרישות: | X12: קליטה | AA12: קליטה לאורך כל המקטעים במסלול. | AB12: TRUE | AE12: =IF(L12="א'",IF(RANDBETWEEN(0,1)=0,"ב'","ג'"),IF(M12="ב'",IF(RANDBETWEEN(0,1)=0,"א'","ג'"),IF(RANDBETWEEN(0,1)=0,"א'","ב'"))) -> א'
A13: SCN_012 | B13: הרצליה | C13: =A13&"_H" -> SCN_012_H | D13: =A13&"_R" -> SCN_012_R | E13: =A13&"_S" -> SCN_012_S | F13: 2 | G13: 2 | H13: 1 | I13: LTR | J13: N | K13: H | L13: ב' | M13: א' | N13: לפי הוויזואליזציה (בפאנל התחתון) איזה מסלול הציג את הציונים הגבוהים ביותר בקטגוריית קליטה? | O13: מסלול א מסלול ב מסלול ג לא יודע/ת | P13: מסלול א, מסלול ב | Q13: לפי הוויזואליזציה (בפאנל התחתון) איזה מסלול הציג את הציונים הנמוכים ביותר בקטגוריית נוף? | R13: מסלול א מסלול ב מסלול ג לא יודע/ת | S13: מסלול א | W13: במפה שלפניך מופיעים 3 מסלולים אפשריים בין נקודת המוצא ליעד. בחר ואשר את המסלול שמתעדף את הדרישות: | X13: קליטה | Y13: 2 | Z13: חיסכון | AA13: קליטה לאורך כל המקטעים במסלול. במקטע 2 גם חיסכון. | AB13: TRUE | AE13: =IF(L13="א'",IF(RANDBETWEEN(0,1)=0,"ב'","ג'"),IF(M13="ב'",IF(RANDBETWEEN(0,1)=0,"א'","ג'"),IF(RANDBETWEEN(0,1)=0,"א'","ב'"))) -> ב'
A14: SCN_013 | B14: יבנה | C14: =A14&"_H" -> SCN_013_H | D14: =A14&"_R" -> SCN_013_R | E14: =A14&"_S" -> SCN_013_S | F14: 2 | G14: 1 | H14: 2 | I14: RTL | J14: N | K14: H | L14: ב' | M14: א' | N14: לפי הוויזואליזציה (בפאנל התחתון) איזה מסלול הציג את הציונים הגבוהים ביותר בקטגוריית קליטה? | O14: מסלול א מסלול ב מסלול ג לא יודע/ת | P14: מסלול ב | Q14: לפי הוויזואליזציה (בפאנל התחתון) איזה מסלול הציג את הציונים הגבוהים ביותר בקטגוריית חיסכון? | R14: מסלול א מסלול ב מסלול ג לא יודע/ת | S14: מסלול ב, מסלול ג | W14: במפה שלפניך מופיעים 3 מסלולים אפשריים בין נקודת המוצא ליעד. בחר ואשר את המסלול שמתעדף את הדרישות: | X14: נוף | Y14: 2 | Z14: קליטה | AA14: נוף לאורך כל המקטעים במסלול. במקטע 2 גם קליטה. | AB14: TRUE | AE14: =IF(L14="א'",IF(RANDBETWEEN(0,1)=0,"ב'","ג'"),IF(M14="ב'",IF(RANDBETWEEN(0,1)=0,"א'","ג'"),IF(RANDBETWEEN(0,1)=0,"א'","ב'"))) -> א'
A15: SCN_014 | B15: חדרה | C15: =A15&"_H" -> SCN_014_H | D15: =A15&"_R" -> SCN_014_R | E15: =A15&"_S" -> SCN_014_S | F15: 3 | G15: 1 | H15: 2 | I15: LTR | J15: N | K15: E | L15: א' | M15: ב' | N15: לפי הוויזואליזציה (בפאנל התחתון) איזה מסלול הציג את הציונים הגבוהים ביותר בקטגוריית נוף? | O15: מסלול א מסלול ב מסלול ג לא יודע/ת | P15: מסלול ב | Q15: לפי הוויזואליזציה (בפאנל התחתון) איזה מסלול הציג את הציונים הגבוהים ביותר בקטגוריית חיסכון? | R15: מסלול א מסלול ב מסלול ג לא יודע/ת | S15: מסלול א | W15: במפה שלפניך מופיעים 3 מסלולים אפשריים בין נקודת המוצא ליעד. בחר ואשר את המסלול שמתעדף את הדרישות: | X15: חיסכון | AA15: חיסכון לאורך כל המקטעים במסלול. | AB15: TRUE | AE15: =IF(L15="א'",IF(RANDBETWEEN(0,1)=0,"ב'","ג'"),IF(M15="ב'",IF(RANDBETWEEN(0,1)=0,"א'","ג'"),IF(RANDBETWEEN(0,1)=0,"א'","ב'"))) -> ב'
A16: SCN_015 | B16: זכרון יעקב | C16: =A16&"_H" -> SCN_015_H | D16: =A16&"_R" -> SCN_015_R | E16: =A16&"_S" -> SCN_015_S | F16: 2 | G16: 2 | H16: 1 | I16: LTR | J16: N | K16: E | L16: ג' | M16: ב' | N16: לפי הוויזואליזציה (בפאנל התחתון) איזה מסלול הציג את הציונים הגבוהים ביותר בקטגוריית נוף? | O16: מסלול א מסלול ב מסלול ג לא יודע/ת | P16: מסלול ב | Q16: לפי הוויזואליזציה (בפאנל התחתון) איזה מסלול הציג את הציונים הנמוכים ביותר בקטגוריית קליטה? | R16: מסלול א מסלול ב מסלול ג לא יודע/ת | S16: מסלול ב | W16: במפה שלפניך מופיעים 3 מסלולים אפשריים בין נקודת המוצא ליעד. בחר ואשר את המסלול שמתעדף את הדרישות: | X16: חיסכון | AA16: חיסכון לאורך כל המקטעים במסלול. | AB16: TRUE | AE16: =IF(L16="א'",IF(RANDBETWEEN(0,1)=0,"ב'","ג'"),IF(M16="ב'",IF(RANDBETWEEN(0,1)=0,"א'","ג'"),IF(RANDBETWEEN(0,1)=0,"א'","ב'"))) -> ג'
A17: SCN_016 | B17: טירת כרמל | C17: =A17&"_H" -> SCN_016_H | D17: =A17&"_R" -> SCN_016_R | E17: =A17&"_S" -> SCN_016_S | F17: 2 | G17: 2 | H17: 2 | I17: RTL | J17: N | K17: H | L17: ב' | M17: ג' | N17: לפי הוויזואליזציה (בפאנל התחתון) איזה מסלול הציג את הציונים הנמוכים ביותר בקטגוריית חיסכון? | O17: מסלול א מסלול ב מסלול ג לא יודע/ת | P17: מסלול ב, מסלול ג | Q17: לפי הוויזואליזציה (בפאנל התחתון) איזה מסלול הציג את הציונים הנמוכים ביותר בקטגוריית קליטה? | R17: מסלול א מסלול ב מסלול ג לא יודע/ת | S17: מסלול א | W17: במפה שלפניך מופיעים 3 מסלולים אפשריים בין נקודת המוצא ליעד. בחר ואשר את המסלול שמתעדף את הדרישות: | X17: קליטה | Y17: 2 | Z17: נוף | AA17: קליטה לאורך כל המקטעים במסלול. במקטע 2 גם נוף. | AB17: TRUE | AE17: =IF(L17="א'",IF(RANDBETWEEN(0,1)=0,"ב'","ג'"),IF(M17="ב'",IF(RANDBETWEEN(0,1)=0,"א'","ג'"),IF(RANDBETWEEN(0,1)=0,"א'","ב'"))) -> א'
A18: SCN_017 | B18: טבריה | C18: =A18&"_H" -> SCN_017_H | D18: =A18&"_R" -> SCN_017_R | E18: =A18&"_S" -> SCN_017_S | F18: 3 | G18: 1 | H18: 2 | I18: RTL | J18: N | K18: E | L18: ג' | M18: א' | N18: לפי הוויזואליזציה (בפאנל התחתון) איזה מסלול הציג את הציונים הנמוכים ביותר בקטגוריית חיסכון? | O18: מסלול א מסלול ב מסלול ג לא יודע/ת | P18: מסלול א | Q18: לפי הוויזואליזציה (בפאנל התחתון) איזה מסלול הציג את הציונים הנמוכים ביותר בקטגוריית נוף? | R18: מסלול א מסלול ב מסלול ג לא יודע/ת | S18: מסלול א, מסלול ב | W18: במפה שלפניך מופיעים 3 מסלולים אפשריים בין נקודת המוצא ליעד. בחר ואשר את המסלול שמתעדף את הדרישות: | X18: קליטה | AA18: קליטה לאורך כל המקטעים במסלול. | AB18: TRUE | AE18: =IF(L18="א'",IF(RANDBETWEEN(0,1)=0,"ב'","ג'"),IF(M18="ב'",IF(RANDBETWEEN(0,1)=0,"א'","ג'"),IF(RANDBETWEEN(0,1)=0,"א'","ב'"))) -> א'
A19: SCN_018 | B19: ירוחם | C19: =A19&"_H" -> SCN_018_H | D19: =A19&"_R" -> SCN_018_R | E19: =A19&"_S" -> SCN_018_S | F19: 2 | G19: 2 | H19: 3 | I19: RTL | J19: N | K19: H | L19: א' | M19: ב' | N19: לפי הוויזואליזציה (בפאנל התחתון) איזה מסלול הציג את הציונים הגבוהים ביותר בקטגוריית קליטה? | O19: מסלול א מסלול ב מסלול ג לא יודע/ת | P19: מסלול ג | Q19: לפי הוויזואליזציה (בפאנל התחתון) איזה מסלול הציג את הציונים הנמוכים ביותר בקטגוריית נוף? | R19: מסלול א מסלול ב מסלול ג לא יודע/ת | S19: מסלול ב | W19: במפה שלפניך מופיעים 3 מסלולים אפשריים בין נקודת המוצא ליעד. בחר ואשר את המסלול שמתעדף את הדרישות: | X19: חיסכון | Y19: 3 | Z19: קליטה | AA19: חיסכון לאורך כל המקטעים במסלול. במקטע 1 גם קליטה. | AB19: TRUE | AE19: =IF(L19="א'",IF(RANDBETWEEN(0,1)=0,"ב'","ג'"),IF(M19="ב'",IF(RANDBETWEEN(0,1)=0,"א'","ג'"),IF(RANDBETWEEN(0,1)=0,"א'","ב'"))) -> ג'
A20: SCN_019 | B20: ירושלים מרכז | C20: =A20&"_H" -> SCN_019_H | D20: =A20&"_R" -> SCN_019_R | E20: =A20&"_S" -> SCN_019_S | F20: 2 | G20: 2 | H20: 0 | I20: RTL | J20: N | K20: E | L20: ג' | M20: א' | N20: לפי הוויזואליזציה (בפאנל התחתון) איזה מסלול הציג את הציונים הגבוהים ביותר בקטגוריית קליטה? | O20: מסלול א מסלול ב מסלול ג לא יודע/ת | P20: מסלול ג | Q20: לפי הוויזואליזציה (בפאנל התחתון) איזה מסלול הציג את הציונים הגבוהים ביותר בקטגוריית חיסכון? | R20: מסלול א מסלול ב מסלול ג לא יודע/ת | S20: מסלול ב, מסלול ג | W20: במפה שלפניך מופיעים 3 מסלולים אפשריים בין נקודת המוצא ליעד. בחר ואשר את המסלול שמתעדף את הדרישות: | X20: חיסכון | AA20: חיסכון לאורך כל המקטעים במסלול. | AB20: TRUE | AE20: =IF(L20="א'",IF(RANDBETWEEN(0,1)=0,"ב'","ג'"),IF(M20="ב'",IF(RANDBETWEEN(0,1)=0,"א'","ג'"),IF(RANDBETWEEN(0,1)=0,"א'","ב'"))) -> ב'
A21: SCN_020 | B21: מגדל העמק | C21: =A21&"_H" -> SCN_020_H | D21: =A21&"_R" -> SCN_020_R | E21: =A21&"_S" -> SCN_020_S | F21: 2 | G21: 2 | H21: 0 | I21: RTL | J21: N | K21: H | L21: ג' | M21: ב' | N21: לפי הוויזואליזציה (בפאנל התחתון) איזה מסלול הציג את הציונים הגבוהים ביותר בקטגוריית נוף? | O21: מסלול א מסלול ב מסלול ג לא יודע/ת | P21: מסלול ג | Q21: לפי הוויזואליזציה (בפאנל התחתון) איזה מסלול הציג את הציונים הגבוהים ביותר בקטגוריית חיסכון? | R21: מסלול א מסלול ב מסלול ג לא יודע/ת | S21: מסלול ג | W21: במפה שלפניך מופיעים 3 מסלולים אפשריים בין נקודת המוצא ליעד. בחר ואשר את המסלול שמתעדף את הדרישות: | X21: חיסכון | Y21: 2 | Z21: נוף | AA21: חיסכון לאורך כל המקטעים במסלול. במקטע 2 גם נוף. | AB21: TRUE | AE21: =IF(L21="א'",IF(RANDBETWEEN(0,1)=0,"ב'","ג'"),IF(M21="ב'",IF(RANDBETWEEN(0,1)=0,"א'","ג'"),IF(RANDBETWEEN(0,1)=0,"א'","ב'"))) -> א'
A22: SCN_021 | B22: מעלות | C22: =A22&"_H" -> SCN_021_H | D22: =A22&"_R" -> SCN_021_R | E22: =A22&"_S" -> SCN_021_S | F22: 1 | G22: 1 | H22: 3 | I22: RTL | J22: N | K22: E | L22: ב' | M22: ג' | N22: לפי הוויזואליזציה (בפאנל התחתון) איזה מסלול הציג את הציונים הגבוהים ביותר בקטגוריית נוף? | O22: מסלול א מסלול ב מסלול ג לא יודע/ת | P22: מסלול ב | Q22: לפי הוויזואליזציה (בפאנל התחתון) איזה מסלול הציג את הציונים הנמוכים ביותר בקטגוריית קליטה? | R22: מסלול א מסלול ב מסלול ג לא יודע/ת | S22: מסלול א | W22: במפה שלפניך מופיעים 3 מסלולים אפשריים בין נקודת המוצא ליעד. בחר ואשר את המסלול שמתעדף את הדרישות: | X22: נוף | AA22: נוף לאורך כל המקטעים במסלול. | AB22: TRUE | AE22: =IF(L22="א'",IF(RANDBETWEEN(0,1)=0,"ב'","ג'"),IF(M22="ב'",IF(RANDBETWEEN(0,1)=0,"א'","ג'"),IF(RANDBETWEEN(0,1)=0,"א'","ב'"))) -> א'
A23: SCN_022 | B23: נס ציונה | C23: =A23&"_H" -> SCN_022_H | D23: =A23&"_R" -> SCN_022_R | E23: =A23&"_S" -> SCN_022_S | F23: 2 | G23: 1 | H23: 2 | I23: LTR | J23: N | K23: H | L23: א' | M23: ב' | N23: לפי הוויזואליזציה (בפאנל התחתון) איזה מסלול הציג את הציונים הנמוכים ביותר בקטגוריית חיסכון? | O23: מסלול א מסלול ב מסלול ג לא יודע/ת | P23: מסלול א | Q23: לפי הוויזואליזציה (בפאנל התחתון) איזה מסלול הציג את הציונים הנמוכים ביותר בקטגוריית קליטה? | R23: מסלול א מסלול ב מסלול ג לא יודע/ת | S23: מסלול א | W23: במפה שלפניך מופיעים 3 מסלולים אפשריים בין נקודת המוצא ליעד. בחר ואשר את המסלול שמתעדף את הדרישות: | X23: נוף | Y23: 3 | Z23: קליטה | AA23: נוף לאורך כל המקטעים במסלול. במקטע 3 גם קליטה. | AB23: TRUE | AE23: =IF(L23="א'",IF(RANDBETWEEN(0,1)=0,"ב'","ג'"),IF(M23="ב'",IF(RANDBETWEEN(0,1)=0,"א'","ג'"),IF(RANDBETWEEN(0,1)=0,"א'","ב'"))) -> ב'
A24: SCN_023 | B24: נתיבות | C24: =A24&"_H" -> SCN_023_H | D24: =A24&"_R" -> SCN_023_R | E24: =A24&"_S" -> SCN_023_S | F24: 1 | G24: 0 | H24: 2 | I24: LTR | J24: N | K24: E | L24: ג' | M24: א' | N24: לפי הוויזואליזציה (בפאנל התחתון) איזה מסלול הציג את הציונים הנמוכים ביותר בקטגוריית חיסכון? | O24: מסלול א מסלול ב מסלול ג לא יודע/ת | P24: מסלול ב | Q24: לפי הוויזואליזציה (בפאנל התחתון) איזה מסלול הציג את הציונים הנמוכים ביותר בקטגוריית נוף? | R24: מסלול א מסלול ב מסלול ג לא יודע/ת | S24: מסלול ג | W24: במפה שלפניך מופיעים 3 מסלולים אפשריים בין נקודת המוצא ליעד. בחר ואשר את המסלול שמתעדף את הדרישות: | X24: קליטה | AA24: קליטה לאורך כל המקטעים במסלול. | AB24: TRUE | AE24: =IF(L24="א'",IF(RANDBETWEEN(0,1)=0,"ב'","ג'"),IF(M24="ב'",IF(RANDBETWEEN(0,1)=0,"א'","ג'"),IF(RANDBETWEEN(0,1)=0,"א'","ב'"))) -> א'
A25: SCN_024 | B25: נתניה דרום | C25: =A25&"_H" -> SCN_024_H | D25: =A25&"_R" -> SCN_024_R | E25: =A25&"_S" -> SCN_024_S | F25: 2 | G25: 0 | H25: 2 | I25: LTR | J25: N | K25: H | L25: ב' | M25: ג' | N25: לפי הוויזואליזציה (בפאנל התחתון) איזה מסלול הציג את הציונים הגבוהים ביותר בקטגוריית קליטה? | O25: מסלול א מסלול ב מסלול ג לא יודע/ת | P25: מסלול ב | Q25: לפי הוויזואליזציה (בפאנל התחתון) איזה מסלול הציג את הציונים הנמוכים ביותר בקטגוריית נוף? | R25: מסלול א מסלול ב מסלול ג לא יודע/ת | S25: מסלול א, מסלול ב | W25: במפה שלפניך מופיעים 3 מסלולים אפשריים בין נקודת המוצא ליעד. בחר ואשר את המסלול שמתעדף את הדרישות: | X25: קליטה | Y25: 1 | Z25: נוף | AA25: קליטה לאורך כל המקטעים במסלול. במקטע 1 גם נוף. | AB25: TRUE | AE25: =IF(L25="א'",IF(RANDBETWEEN(0,1)=0,"ב'","ג'"),IF(M25="ב'",IF(RANDBETWEEN(0,1)=0,"א'","ג'"),IF(RANDBETWEEN(0,1)=0,"א'","ב'"))) -> ב'
A26: SCN_025 | B26: ערד | C26: =A26&"_H" -> SCN_025_H | D26: =A26&"_R" -> SCN_025_R | E26: =A26&"_S" -> SCN_025_S | F26: 1 | G26: 2 | H26: 2 | I26: LTR | J26: N | K26: E | L26: ג' | M26: א' | N26: לפי הוויזואליזציה (בפאנל התחתון) איזה מסלול הציג את הציונים הגבוהים ביותר בקטגוריית קליטה? | O26: מסלול א מסלול ב מסלול ג לא יודע/ת | P26: מסלול ג | Q26: לפי הוויזואליזציה (בפאנל התחתון) איזה מסלול הציג את הציונים הגבוהים ביותר בקטגוריית חיסכון? | R26: מסלול א מסלול ב מסלול ג לא יודע/ת | S26: מסלול ג | W26: במפה שלפניך מופיעים 3 מסלולים אפשריים בין נקודת המוצא ליעד. בחר ואשר את המסלול שמתעדף את הדרישות: | X26: נוף | AA26: נוף לאורך כל המקטעים במסלול. | AB26: TRUE | AE26: =IF(L26="א'",IF(RANDBETWEEN(0,1)=0,"ב'","ג'"),IF(M26="ב'",IF(RANDBETWEEN(0,1)=0,"א'","ג'"),IF(RANDBETWEEN(0,1)=0,"א'","ב'"))) -> ב'
